tests/medium-example1.in
# 2 threads, 3 instruments
2
0-1 o
.
0 S 1 MSFT 86029 7685
1 S 2 AMZN 149662 9910
0 B 3 MSFT 59186 3031
1 S 4 AAPL 157354 2818
0 B 5 MSFT 171110 9609
1 B 6 MSFT 22841 4064
1 B 7 MSFT 6568 7603
1 S 8 MSFT 108184 5120
1 B 9 AMZN 78878 3014
1 S 10 AAPL 196895 6780
0 S 11 AMZN 45733 6389
0 S 12 MSFT 119412 9228
1 S 13 AAPL 144301 4485
0 B 14 MSFT 44847 9538
0 B 15 AAPL 87635 2814
0 S 16 MSFT 183548 4718
0 S 17 AMZN 126957 2128
0 B 18 AMZN 173453 840
1 B 19 AAPL 160999 1240
0 S 20 AAPL 175382 7475
1 S 21 AAPL 104967 1180
1 S 22 AMZN 190738 4538
0 S 23 AMZN 125152 619
1 B 24 AMZN 161216 7433
1 S 25 AAPL 197888 5474
0 B 26 AMZN 134412 4520
1 B 27 AAPL 159018 2303
0 B 28 MSFT 75316 2558
0 S 29 AMZN 75466 5468
1 B 30 AMZN 27479 330
0 S 31 AMZN 150520 7190
0 S 32 AAPL 113329 6060
0 B 33 AMZN 172128 7360
0 S 34 AAPL 121722 2210
0 B 35 AAPL 6856 6754
1 S 36 AMZN 157495 1304
0 B 37 AMZN 98443 5763
1 S 38 AAPL 101480 1508
1 S 39 MSFT 110871 5594
0 B 40 AAPL 21377 3717
0 S 41 AMZN 48548 7913
0 S 42 AAPL 107868 1656
0 S 43 MSFT 170614 550
1 B 44 MSFT 60008 4386
0 S 45 AAPL 82926 1383
0 S 46 AAPL 115927 5659
1 B 47 AMZN 136082 7696
1 S 48 MSFT 119988 2026
0 B 49 AAPL 142731 1851
0 S 50 AMZN 77974 9021
1 B 51 AAPL 153644 2999
1 B 52 MSFT 74737 3756
0 S 53 MSFT 50714 8746
1 B 54 AAPL 38725 5207
1 S 55 AAPL 36577 3918
0 B 56 AAPL 45704 6197
0 S 57 AAPL 179928 3253
0 S 58 AAPL 27248 8407
1 B 59 MSFT 22413 5939
0 S 60 AMZN 174426 8118
0 S 61 MSFT 193762 1040
1 S 62 AAPL 196853 5018
1 S 63 AAPL 55087 8113
0 S 64 AMZN 55557 3563
1 S 65 AMZN 75 3886
1 B 66 MSFT 86034 7997
1 B 67 AAPL 60519 4874
1 B 68 MSFT 178836 8504
1 B 69 MSFT 180538 2940
1 S 70 AMZN 171787 6819
0 B 71 AAPL 37082 6136
0 B 72 AAPL 123354 1905
1 B 73 AAPL 151887 7357
1 S 74 MSFT 78503 1889
0 B 75 AMZN 184796 2749
1 B 76 AAPL 60089 4460
0 S 77 AAPL 158547 3416
0 B 78 AMZN 178223 4551
1 B 79 AAPL 81098 8777
0 B 80 MSFT 166626 3135
0 B 81 AAPL 86767 9642
0 B 82 MSFT 144923 3351
1 B 83 AMZN 72214 9825
0 S 84 AAPL 160636 11
0 B 85 MSFT 79617 7434
1 B 86 MSFT 192595 3466
1 B 87 AMZN 128771 9208
1 S 88 AMZN 155065 860
0 S 89 AMZN 121202 1626
1 S 90 MSFT 164024 4598
0 S 91 AAPL 54380 7622
0 S 92 MSFT 98136 5563
0 S 93 MSFT 173634 4433
0 B 94 MSFT 155156 375
0 S 95 MSFT 148918 9617
1 B 96 MSFT 65936 7193
1 B 97 AAPL 97709 2122
0 S 98 AMZN 52154 837
1 B 99 MSFT 76045 791
0 B 100 AMZN 100835 3184
0 S 101 MSFT 3778 4862
0 S 102 AAPL 156402 9595
1 B 103 AMZN 170793 7096
0 B 104 MSFT 186631 9021
0 B 105 MSFT 33306 4357
0 S 106 AMZN 146537 6164
1 B 107 MSFT 95769 7412
0 B 108 MSFT 20805 5346
1 B 109 AMZN 125322 8634
1 B 110 AAPL 97835 2367
1 B 111 AMZN 73062 8232
0 B 112 AAPL 179970 9077
1 S 113 AAPL 80954 4270
0 S 114 MSFT 36378 6774
1 S 115 AMZN 124507 2201
1 S 116 MSFT 71643 6928
1 S 117 AAPL 90332 6893
1 S 118 AAPL 33735 9575
1 S 119 AAPL 102833 9912
0 B 120 MSFT 141866 4576
1 S 121 AAPL 36605 4387
0 S 122 AAPL 109286 1409
0 B 123 AAPL 155762 4909
0 B 124 MSFT 46551 8556
1 S 125 MSFT 52874 5087
1 S 126 AAPL 191031 5176
0 S 127 MSFT 73957 6873
0 S 128 AMZN 168659 3362
0 B 129 MSFT 128143 201
1 B 130 MSFT 81228 2336
1 S 131 AAPL 17825 10
1 B 132 MSFT 187039 4717
1 S 133 MSFT 120920 7685
1 B 134 AAPL 109268 2789
0 S 135 AAPL 64755 2059
0 S 136 MSFT 80376 7790
1 B 137 MSFT 89326 4448
0 S 138 AAPL 107905 7312
1 S 139 MSFT 24945 5054
1 B 140 AAPL 79449 8937
1 B 141 AAPL 4906 2778
1 S 142 MSFT 188884 4871
1 S 143 MSFT 75193 3837
1 S 144 AAPL 141353 528
0 S 145 AAPL 196795 1499
1 B 146 MSFT 69713 8819
0 S 147 AAPL 104904 386
0 S 148 AAPL 63501 5267
1 B 149 AAPL 158717 520
0 B 150 AAPL 145100 89
0 B 151 AMZN 75300 6216
0 S 152 MSFT 142315 1291
0 S 153 MSFT 68057 7761
1 S 154 AMZN 147062 4750
0 B 155 AMZN 154610 4051
0 S 156 AMZN 20770 1306
1 B 157 MSFT 166469 5182
1 S 158 MSFT 110112 4435
1 B 159 AAPL 7514 6069
0 B 160 AAPL 199722 8659
1 S 161 AAPL 1282 4565
1 B 162 AAPL 146779 6491
0 B 163 MSFT 13787 7424
1 B 164 MSFT 83061 480
1 B 165 AAPL 50317 3098
1 B 166 MSFT 192454 5845
0 B 167 AAPL 47147 1846
0 B 168 AMZN 62538 9402
1 B 169 AAPL 10509 2096
0 S 170 MSFT 159220 3017
1 S 171 AMZN 157443 4156
0 S 172 AAPL 126040 8711
1 S 173 MSFT 136684 5292
1 S 174 AMZN 64175 4780
1 S 175 MSFT 25549 9427
1 S 176 AAPL 16455 2700
0 S 177 MSFT 862 691
1 B 178 MSFT 46322 5568
1 S 179 AMZN 7061 211
0 S 180 MSFT 161390 1592
1 S 181 AAPL 166061 8075
0 S 182 AAPL 91692 1624
0 S 183 AAPL 22995 8627
0 S 184 MSFT 84087 5655
1 B 185 AAPL 199009 4332
0 S 186 AMZN 115338 932
0 B 187 AAPL 29442 7336
1 B 188 MSFT 173311 3610
0 S 189 MSFT 115015 2049
1 B 190 MSFT 162776 3060
1 S 191 MSFT 123834 2776
0 B 192 MSFT 126922 2087
1 B 193 MSFT 88471 9306
0 B 194 AAPL 51807 5495
1 S 195 AAPL 124717 2300
1 S 196 AAPL 15348 718
0 B 197 AAPL 105261 7466
0 B 198 AMZN 38749 6956
1 S 199 AMZN 150797 5810
0 B 200 AAPL 96374 8806
0 S 201 AMZN 163855 8251
1 S 202 MSFT 83308 6856
1 S 203 AAPL 182147 7261
0 B 204 MSFT 169843 2745
0 S 205 AAPL 103454 7134
1 S 206 AAPL 28195 7759
1 B 207 MSFT 149589 5061
1 B 208 AAPL 116837 7190
1 S 209 AAPL 88344 4898
1 B 210 AAPL 21179 4769
1 B 211 AMZN 88344 7988
0 S 212 AAPL 35414 7340
1 B 213 AAPL 139568 970
0 B 214 AAPL 87252 7673
0 B 215 AMZN 131818 5058
0 B 216 AAPL 16311 5676
0 S 217 MSFT 154183 5460
1 S 218 AMZN 187691 1973
0 S 219 AMZN 80201 8774
1 B 220 AMZN 194256 1782
1 B 221 AAPL 52501 4267
0 B 222 MSFT 132715 6719
1 B 223 AMZN 187062 8482
0 B 224 MSFT 102159 1472
1 B 225 AMZN 98840 9192
0 B 226 MSFT 53517 1916
1 S 227 AMZN 94873 6138
0 B 228 AAPL 180590 4311
1 B 229 AAPL 90437 2217
0 S 230 MSFT 141703 1388
1 B 231 MSFT 157089 71
1 B 232 AAPL 91873 2343
0 B 233 AMZN 128467 6060
0 B 234 AAPL 145204 9057
0 S 235 MSFT 90810 9651
1 B 236 MSFT 143711 3884
1 B 237 MSFT 16292 3403
1 S 238 AMZN 9747 9450
1 S 239 AMZN 23872 8035
1 B 240 MSFT 90736 869
0 B 241 AAPL 151320 6809
0 B 242 AAPL 148668 1993
1 S 243 AMZN 52741 6997
0 S 244 AMZN 108120 9576
0 S 245 MSFT 57323 6937
0 B 246 MSFT 142102 9770
0 B 247 MSFT 10607 44
0 B 248 AMZN 152570 7352
1 B 249 AMZN 80530 1025
1 S 250 MSFT 114090 3198
1 S 251 MSFT 56715 5802
1 B 252 MSFT 80980 8906
1 S 253 MSFT 193111 6512
1 B 254 AAPL 156498 8658
1 S 255 AAPL 33145 4815
0 S 256 AAPL 146171 2928
1 S 257 MSFT 198479 3179
1 B 258 AAPL 89319 3210
1 B 259 AMZN 34441 9585
0 B 260 MSFT 118395 2984
1 S 261 AMZN 158251 4521
1 B 262 AAPL 76732 5550
0 S 263 MSFT 70053 4134
1 B 264 AAPL 27923 196
1 S 265 AAPL 9754 1465
0 B 266 AMZN 99080 1359
0 B 267 AMZN 182513 8997
0 B 268 MSFT 44290 8011
0 B 269 MSFT 168420 5435
0 S 270 AAPL 110261 3662
1 S 271 AMZN 85480 2345
1 B 272 AMZN 74268 5135
0 S 273 MSFT 15060 5754
0 B 274 AAPL 39628 3962
0 B 275 MSFT 124946 9254
0 S 276 AMZN 13359 4323
1 S 277 AMZN 198987 7615
0 S 278 AAPL 163943 2065
1 S 279 AMZN 177079 2759
1 B 280 AAPL 66918 8391
0 S 281 AAPL 98009 9268
0 S 282 MSFT 106209 2877
0 B 283 AMZN 72819 3056
1 S 284 AMZN 166774 6493
1 B 285 AMZN 6805 1521
1 S 286 AMZN 93689 6327
0 S 287 AAPL 28049 595
0 B 288 MSFT 168513 2047
1 S 289 AAPL 58259 9044
0 S 290 AAPL 162595 8164
0 B 291 AAPL 108196 6176
0 B 292 AMZN 50128 8446
0 S 293 AMZN 94122 6138
0 S 294 AAPL 62693 3520
0 B 295 AMZN 199707 2578
0 B 296 AMZN 42885 7469
1 B 297 MSFT 90032 7242
0 S 298 AMZN 58395 1286
0 B 299 AMZN 187989 3846
0 S 300 AMZN 32363 996
1 S 301 MSFT 74446 9787
0 S 302 AAPL 64018 5229
0 B 303 AMZN 12062 5793
1 B 304 AAPL 52432 5304
1 S 305 MSFT 66235 3117
0 S 306 AAPL 170252 6258
0 S 307 AMZN 69537 3473
0 S 308 MSFT 166681 1527
0 S 309 AAPL 144314 9829
0 S 310 MSFT 151260 8676
1 S 311 AMZN 185632 8398
1 B 312 AMZN 188795 3603
1 S 313 AAPL 179370 4443
0 S 314 MSFT 81143 6655
1 B 315 MSFT 15117 442
1 S 316 AAPL 30656 5196
1 S 317 MSFT 33902 5871
0 B 318 AAPL 85037 4070
1 S 319 MSFT 190967 9549
1 B 320 AMZN 91203 3907
0 S 321 AMZN 46249 1571
0 S 322 AAPL 100719 9106
0 S 323 AAPL 29797 1589
1 B 324 AAPL 69233 4078
0 S 325 AMZN 63671 3450
0 B 326 MSFT 137450 6647
0 B 327 AMZN 145022 2772
0 S 328 AMZN 29016 81
1 B 329 AMZN 84381 3058
1 S 330 MSFT 165280 5194
1 B 331 AMZN 102618 1121
0 B 332 MSFT 155253 8706
