tests/medium-example2.in
# 2 threads, 1 instrument
2
0-1 o
.
1 B 1 AAPL 9070 238
1 B 2 AAPL 2176 423
0 B 3 AAPL 6940 921
0 S 4 AAPL 14594 425
0 S 5 AAPL 13230 417
0 S 6 AAPL 8991 771
0 B 7 AAPL 17700 810
1 S 8 AAPL 5069 321
0 S 9 AAPL 6036 996
1 S 10 AAPL 5996 75
1 S 11 AAPL 2305 793
1 B 12 AAPL 14307 645
0 S 13 AAPL 11279 476
1 B 14 AAPL 11853 473
1 S 15 AAPL 3414 798
0 B 16 AAPL 17513 439
0 S 17 AAPL 7649 346
1 S 18 AAPL 3659 130
1 B 19 AAPL 17327 961
0 S 20 AAPL 11423 105
1 B 21 AAPL 17159 200
0 S 22 AAPL 8970 89
1 S 23 AAPL 7856 462
1 S 24 AAPL 9678 842
1 S 25 AAPL 16206 541
1 B 26 AAPL 8702 927
0 B 27 AAPL 1267 126
0 B 28 AAPL 9411 98
0 S 29 AAPL 6273 639
0 S 30 AAPL 4032 3
1 S 31 AAPL 5581 350
0 B 32 AAPL 13165 744
1 B 33 AAPL 18114 578
1 B 34 AAPL 12249 227
1 S 35 AAPL 12579 915
1 S 36 AAPL 12574 489
1 B 37 AAPL 19489 822
1 B 38 AAPL 19900 1000
1 S 39 AAPL 7287 103
1 B 40 AAPL 19491 245
1 B 41 AAPL 17840 880
1 S 42 AAPL 12654 860
1 B 43 AAPL 5791 561
1 B 44 AAPL 6147 243
0 S 45 AAPL 16915 916
1 S 46 AAPL 5530 515
1 S 47 AAPL 5684 788
1 B 48 AAPL 1055 75
0 B 49 AAPL 2663 787
1 S 50 AAPL 17469 329
0 B 51 AAPL 15110 179
0 S 52 AAPL 11513 74
1 S 53 AAPL 14810 703
0 B 54 AAPL 4760 362
0 B 55 AAPL 7024 789
1 S 56 AAPL 13449 494
0 S 57 AAPL 10033 993
1 S 58 AAPL 2076 188
1 S 59 AAPL 8712 998
1 S 60 AAPL 3095 504
1 S 61 AAPL 17556 819
1 B 62 AAPL 15937 269
0 S 63 AAPL 11462 718
0 S 64 AAPL 5281 267
1 B 65 AAPL 18232 232
1 S 66 AAPL 3900 324
0 S 67 AAPL 2688 181
0 S 68 AAPL 4027 68
1 S 69 AAPL 19891 879
1 B 70 AAPL 10854 266
0 B 71 AAPL 2157 140
0 S 72 AAPL 2302 966
1 B 73 AAPL 2716 558
0 S 74 AAPL 6245 914
1 B 75 AAPL 9504 593
0 B 76 AAPL 15079 169
0 S 77 AAPL 15665 932
0 B 78 AAPL 11722 15
0 B 79 AAPL 14673 197
1 S 80 AAPL 13694 491
0 S 81 AAPL 4984 498
0 S 82 AAPL 13683 961
1 S 83 AAPL 17297 464
1 S 84 AAPL 8921 277
1 B 85 AAPL 8729 956
0 S 86 AAPL 19333 892
1 S 87 AAPL 1188 536
0 S 88 AAPL 18998 870
1 B 89 AAPL 13624 620
0 B 90 AAPL 13129 823
1 B 91 AAPL 13657 476
1 B 92 AAPL 3063 669
1 B 93 AAPL 1379 96
1 B 94 AAPL 7231 631
0 B 95 AAPL 9284 954
0 S 96 AAPL 14432 320
1 B 97 AAPL 16470 933
1 S 98 AAPL 14203 803
1 S 99 AAPL 5480 543
1 S 100 AAPL 7990 319
1 B 101 AAPL 17181 840
0 B 102 AAPL 7322 581
0 S 103 AAPL 2446 844
1 B 104 AAPL 17584 487
0 B 105 AAPL 19973 461
0 S 106 AAPL 3601 970
0 S 107 AAPL 19602 286
0 B 108 AAPL 2172 221
1 S 109 AAPL 8705 882
0 S 110 AAPL 19569 29
1 S 111 AAPL 8525 814
1 B 112 AAPL 15622 510
0 B 113 AAPL 5920 236
0 B 114 AAPL 15422 826
0 S 115 AAPL 10839 918
1 B 116 AAPL 7629 572
1 B 117 AAPL 19425 560
0 S 118 AAPL 17563 869
0 S 119 AAPL 2413 844
1 S 120 AAPL 3166 174
0 B 121 AAPL 14412 749
1 S 122 AAPL 8839 359
1 B 123 AAPL 5483 916
0 S 124 AAPL 15440 893
0 B 125 AAPL 4493 371
1 S 126 AAPL 7023 516
0 B 127 AAPL 4409 581
1 B 128 AAPL 9702 60
1 S 129 AAPL 159 336
0 B 130 AAPL 8331 444
0 S 131 AAPL 5076 192
1 S 132 AAPL 10551 827
0 B 133 AAPL 5154 906
1 B 134 AAPL 5542 999
1 S 135 AAPL 12532 649
1 B 136 AAPL 16333 380
0 S 137 AAPL 8946 395
0 S 138 AAPL 18558 74
1 B 139 AAPL 13363 689
1 S 140 AAPL 2890 368
1 S 141 AAPL 473 202
1 S 142 AAPL 2459 172
1 B 143 AAPL 17720 678
1 B 144 AAPL 2690 242
0 B 145 AAPL 17611 677
0 B 146 AAPL 3965 878
1 S 147 AAPL 4222 733
0 B 148 AAPL 7080 39
1 S 149 AAPL 18994 911
0 B 150 AAPL 4215 512
1 B 151 AAPL 6602 320
1 S 152 AAPL 17462 259
0 S 153 AAPL 17020 433
0 S 154 AAPL 19592 50
1 S 155 AAPL 5880 1
0 B 156 AAPL 18971 57
1 B 157 AAPL 18518 624
1 S 158 AAPL 1944 126
0 S 159 AAPL 8915 377
0 S 160 AAPL 18833 713
1 S 161 AAPL 8252 422
1 S 162 AAPL 17531 304
0 B 163 AAPL 18880 122
1 S 164 AAPL 17710 758
0 S 165 AAPL 11059 528
1 S 166 AAPL 10241 375
0 B 167 AAPL 17228 446
0 S 168 AAPL 16010 637
1 B 169 AAPL 15031 714
0 B 170 AAPL 17896 848
0 S 171 AAPL 16980 149
1 S 172 AAPL 18168 449
0 B 173 AAPL 9694 684
1 B 174 AAPL 18630 315
0 S 175 AAPL 14360 951
0 S 176 AAPL 5625 876
1 S 177 AAPL 16144 878
1 B 178 AAPL 11571 580
1 B 179 AAPL 9430 579
1 B 180 AAPL 5718 609
0 B 181 AAPL 5223 148
0 S 182 AAPL 3913 120
1 S 183 AAPL 14940 249
0 B 184 AAPL 2947 156
1 B 185 AAPL 16129 824
0 S 186 AAPL 15032 852
1 B 187 AAPL 13701 331
1 S 188 AAPL 17933 239
1 S 189 AAPL 9761 90
1 B 190 AAPL 18831 856
1 B 191 AAPL 7471 890
1 S 192 AAPL 18058 840
0 S 193 AAPL 11284 973
1 B 194 AAPL 9436 325
0 B 195 AAPL 976 122
1 B 196 AAPL 13991 715
1 B 197 AAPL 1995 987
1 B 198 AAPL 5207 553
1 S 199 AAPL 10450 447
1 S 200 AAPL 11413 944
0 S 201 AAPL 3496 328
1 B 202 AAPL 17444 885
0 B 203 AAPL 7115 423
0 S 204 AAPL 13749 420
1 B 205 AAPL 17333 962
0 S 206 AAPL 16180 393
0 B 207 AAPL 14956 27
1 B 208 AAPL 1183 772
1 S 209 AAPL 17116 587
0 S 210 AAPL 2808 211
0 B 211 AAPL 9973 115
1 B 212 AAPL 10357 619
1 B 213 AAPL 2363 138
0 B 214 AAPL 9740 580
1 B 215 AAPL 17022 421
1 S 216 AAPL 11674 674
1 S 217 AAPL 8160 705
1 B 218 AAPL 17449 513
1 B 219 AAPL 7585 341
0 B 220 AAPL 15417 529
0 S 221 AAPL 7035 903
1 B 222 AAPL 7082 465
0 S 223 AAPL 11807 321
1 B 224 AAPL 1655 37
0 S 225 AAPL 16557 340
0 S 226 AAPL 1800 951
0 B 227 AAPL 6555 837
0 B 228 AAPL 16992 741
0 S 229 AAPL 9944 720
1 S 230 AAPL 16775 500
0 B 231 AAPL 16307 23
0 S 232 AAPL 15613 483
1 S 233 AAPL 9039 70
1 S 234 AAPL 18640 181
0 S 235 AAPL 5700 689
0 B 236 AAPL 12291 247
1 S 237 AAPL 2038 150
0 B 238 AAPL 13395 907
1 S 239 AAPL 2038 227
0 B 240 AAPL 14439 266
0 S 241 AAPL 3686 819
0 B 242 AAPL 13885 369
0 S 243 AAPL 9465 189
1 B 244 AAPL 784 916
0 S 245 AAPL 13750 154
0 B 246 AAPL 7532 92
1 S 247 AAPL 11291 626
1 B 248 AAPL 15373 969
0 S 249 AAPL 836 313
0 S 250 AAPL 4583 953
1 B 251 AAPL 4014 540
1 S 252 AAPL 2565 463
1 S 253 AAPL 424 387
1 B 254 AAPL 6003 570
0 B 255 AAPL 15653 255
0 B 256 AAPL 17965 457
0 B 257 AAPL 11647 942
0 S 258 AAPL 19010 486
0 B 259 AAPL 2914 597
1 S 260 AAPL 4411 89
0 S 261 AAPL 1224 462
1 S 262 AAPL 14010 654
1 S 263 AAPL 11933 914
0 S 264 AAPL 8384 17
1 B 265 AAPL 1839 689
0 S 266 AAPL 16535 170
1 B 267 AAPL 14309 699
0 B 268 AAPL 5295 186
1 S 269 AAPL 10732 995
1 S 270 AAPL 10947 403
0 S 271 AAPL 12581 859
1 B 272 AAPL 10564 303
1 B 273 AAPL 10455 917
1 S 274 AAPL 12844 308
0 S 275 AAPL 13523 568
1 B 276 AAPL 9493 872
0 B 277 AAPL 13921 889
0 B 278 AAPL 7465 404
1 S 279 AAPL 16297 325
0 S 280 AAPL 4858 906
0 B 281 AAPL 12281 738
1 B 282 AAPL 4269 939
1 B 283 AAPL 1992 904
0 B 284 AAPL 8436 803
0 B 285 AAPL 12140 953
1 S 286 AAPL 10650 4
0 B 287 AAPL 18934 474
1 B 288 AAPL 10944 406
1 S 289 AAPL 15307 125
0 B 290 AAPL 17856 889
0 S 291 AAPL 13564 534
1 B 292 AAPL 17697 197
1 S 293 AAPL 11583 961
0 S 294 AAPL 15061 878
1 S 295 AAPL 17683 453
0 S 296 AAPL 9829 604
1 S 297 AAPL 12451 624
0 S 298 AAPL 19209 603
0 S 299 AAPL 17601 963
0 S 300 AAPL 13638 582
1 B 301 AAPL 10868 91
1 S 302 AAPL 9771 562
1 B 303 AAPL 18015 211
0 S 304 AAPL 9649 353
0 S 305 AAPL 12212 6
1 S 306 AAPL 6558 250
0 S 307 AAPL 9984 675
0 B 308 AAPL 14088 222
1 S 309 AAPL 3529 452
0 S 310 AAPL 12109 713
0 B 311 AAPL 12293 133
0 S 312 AAPL 175 980
0 B 313 AAPL 11709 261
0 S 314 AAPL 13439 414
0 S 315 AAPL 4002 918
1 B 316 AAPL 7767 314
1 B 317 AAPL 13410 873
0 S 318 AAPL 12546 734
0 S 319 AAPL 10141 126
1 B 320 AAPL 9381 305
1 B 321 AAPL 5220 444
0 S 322 AAPL 16610 918
0 B 323 AAPL 5066 852
1 S 324 AAPL 3713 447
0 S 325 AAPL 18866 48
0 B 326 AAPL 11593 567
0 S 327 AAPL 3970 669
0 B 328 AAPL 12977 5
1 B 329 AAPL 4877 196
0 S 330 AAPL 633 361
1 B 331 AAPL 19814 804
0 B 332 AAPL 12217 814
0 B 333 AAPL 7686 531
1 S 334 AAPL 2171 287
0 S 335 AAPL 15643 132
1 S 336 AAPL 15009 283
0 S 337 AAPL 13330 480
1 S 338 AAPL 13921 116
0 S 339 AAPL 13084 556
0 S 340 AAPL 12551 943
0 B 341 AAPL 5837 54
1 S 342 AAPL 14479 245
0 B 343 AAPL 12692 510
1 B 344 AAPL 15834 389
0 B 345 AAPL 10828 689
1 B 346 AAPL 14714 524
1 S 347 AAPL 9883 627
1 B 348 AAPL 139 14
0 B 349 AAPL 9269 983
0 B 350 AAPL 3295 362
0 S 351 AAPL 1136 444
1 B 352 AAPL 7938 982
0 S 353 AAPL 896 933
1 S 354 AAPL 5708 298
1 S 355 AAPL 1952 560
0 S 356 AAPL 8765 919
1 B 357 AAPL 18493 637
0 B 358 AAPL 912 598
1 S 359 AAPL 19755 854
0 B 360 AAPL 5294 939
0 S 361 AAPL 11505 850
